Traceback (most recent call last):
  File "/usr/lib64/python2.6/logging/__init__.py", line 808, in emit
    self.flush()
  File "/usr/lib64/python2.6/logging/__init__.py", line 770, in flush
    self.stream.flush()
IOError: [Errno 116] Stale file handle

INFO 	2016-06-02 18:00:32 	[configuration] 	script to access/write from/to metadata: /users/project/4DGenome/utils/io_metadata.sh
INFO 	2016-06-02 18:00:32 	[configuration] 	metadata database: /users/project/4DGenome/data/4DGenome_metadata.db
INFO 	2016-06-02 18:00:32 	[configuration] 	data for 3915492f5_daf5eda58 will be stored at /users/project/4DGenome_no_backup/data/hic/samples/3915492f5_daf5eda58
INFO 	2016-06-02 18:00:32 	[configuration] 	paths to input FASTQ files extracted from the metadata
INFO 	2016-06-02 18:01:02 	[configuration] 	species (Homo_sapiens) and assembly version (hg38_mmtv) extracted from the metadata
Traceback (most recent call last):
  File "/users/project/4DGenome/utils/io_metadata.py", line 100, in <module>
    tab.upsert(new_data, ['SAMPLE_ID'])
  File "/software/mb/el6.3/Conda/lib/python2.7/site-packages/dataset/persistence/table.py", line 171, in upsert
    row_count = self.update(row, keys, ensure=ensure, types=types)
  File "/software/mb/el6.3/Conda/lib/python2.7/site-packages/dataset/persistence/table.py", line 144, in update
    rp = self.database.executable.execute(stmt)
  File "/software/mb/el6.3/Conda/lib/python2.7/site-packages/sqlalchemy/engine/base.py", line 1991, in execute
    return connection.execute(statement, *multiparams, **params)
  File "/software/mb/el6.3/Conda/lib/python2.7/site-packages/sqlalchemy/engine/base.py", line 914, in execute
    return meth(self, multiparams, params)
  File "/software/mb/el6.3/Conda/lib/python2.7/site-packages/sqlalchemy/sql/elements.py", line 323, in _execute_on_connection
    return connection._execute_clauseelement(self, multiparams, params)
  File "/software/mb/el6.3/Conda/lib/python2.7/site-packages/sqlalchemy/engine/base.py", line 1010, in _execute_clauseelement
    compiled_sql, distilled_params
  File "/software/mb/el6.3/Conda/lib/python2.7/site-packages/sqlalchemy/engine/base.py", line 1146, in _execute_context
    context)
  File "/software/mb/el6.3/Conda/lib/python2.7/site-packages/sqlalchemy/engine/base.py", line 1341, in _handle_dbapi_exception
    exc_info
  File "/software/mb/el6.3/Conda/lib/python2.7/site-packages/sqlalchemy/util/compat.py", line 200, in raise_from_cause
    reraise(type(exception), exception, tb=exc_tb, cause=cause)
  File "/software/mb/el6.3/Conda/lib/python2.7/site-packages/sqlalchemy/engine/base.py", line 1139, in _execute_context
    context)
  File "/software/mb/el6.3/Conda/lib/python2.7/site-packages/sqlalchemy/engine/default.py", line 450, in do_execute
    cursor.execute(statement, parameters)
sqlalchemy.exc.OperationalError: (sqlite3.OperationalError) database is locked [SQL: u'UPDATE hic SET "PIPELINE_RUN_MODE"=? WHERE hic."SAMPLE_ID" = ?'] [parameters: ('full', '3915492f5_daf5eda58')]
Traceback (most recent call last):
  File "/users/project/4DGenome/utils/io_metadata.py", line 107, in <module>
    tab.upsert(new_data, ['JOB_ID'])
  File "/software/mb/el6.3/Conda/lib/python2.7/site-packages/dataset/persistence/table.py", line 182, in upsert
    return self.insert(row, ensure=ensure, types=types)
  File "/software/mb/el6.3/Conda/lib/python2.7/site-packages/dataset/persistence/table.py", line 74, in insert
    res = self.database.executable.execute(self.table.insert(row))
  File "/software/mb/el6.3/Conda/lib/python2.7/site-packages/sqlalchemy/engine/base.py", line 1991, in execute
    return connection.execute(statement, *multiparams, **params)
  File "/software/mb/el6.3/Conda/lib/python2.7/site-packages/sqlalchemy/engine/base.py", line 914, in execute
    return meth(self, multiparams, params)
  File "/software/mb/el6.3/Conda/lib/python2.7/site-packages/sqlalchemy/sql/elements.py", line 323, in _execute_on_connection
    return connection._execute_clauseelement(self, multiparams, params)
  File "/software/mb/el6.3/Conda/lib/python2.7/site-packages/sqlalchemy/engine/base.py", line 1010, in _execute_clauseelement
    compiled_sql, distilled_params
  File "/software/mb/el6.3/Conda/lib/python2.7/site-packages/sqlalchemy/engine/base.py", line 1146, in _execute_context
    context)
  File "/software/mb/el6.3/Conda/lib/python2.7/site-packages/sqlalchemy/engine/base.py", line 1341, in _handle_dbapi_exception
    exc_info
  File "/software/mb/el6.3/Conda/lib/python2.7/site-packages/sqlalchemy/util/compat.py", line 200, in raise_from_cause
    reraise(type(exception), exception, tb=exc_tb, cause=cause)
  File "/software/mb/el6.3/Conda/lib/python2.7/site-packages/sqlalchemy/engine/base.py", line 1139, in _execute_context
    context)
  File "/software/mb/el6.3/Conda/lib/python2.7/site-packages/sqlalchemy/engine/default.py", line 450, in do_execute
    cursor.execute(statement, parameters)
sqlalchemy.exc.OperationalError: (sqlite3.OperationalError) database is locked [SQL: u'INSERT INTO jobs ("JOB_ID", "QUEUE") VALUES (?, ?)'] [parameters: ('3915492f5_daf5eda58;2016-06-02-18-00', 'long-sl65')]
Traceback (most recent call last):
  File "/users/project/4DGenome/utils/io_metadata.py", line 100, in <module>
    tab.upsert(new_data, ['SAMPLE_ID'])
  File "/software/mb/el6.3/Conda/lib/python2.7/site-packages/dataset/persistence/table.py", line 171, in upsert
    row_count = self.update(row, keys, ensure=ensure, types=types)
  File "/software/mb/el6.3/Conda/lib/python2.7/site-packages/dataset/persistence/table.py", line 144, in update
    rp = self.database.executable.execute(stmt)
  File "/software/mb/el6.3/Conda/lib/python2.7/site-packages/sqlalchemy/engine/base.py", line 1991, in execute
    return connection.execute(statement, *multiparams, **params)
  File "/software/mb/el6.3/Conda/lib/python2.7/site-packages/sqlalchemy/engine/base.py", line 914, in execute
    return meth(self, multiparams, params)
  File "/software/mb/el6.3/Conda/lib/python2.7/site-packages/sqlalchemy/sql/elements.py", line 323, in _execute_on_connection
    return connection._execute_clauseelement(self, multiparams, params)
  File "/software/mb/el6.3/Conda/lib/python2.7/site-packages/sqlalchemy/engine/base.py", line 1010, in _execute_clauseelement
    compiled_sql, distilled_params
  File "/software/mb/el6.3/Conda/lib/python2.7/site-packages/sqlalchemy/engine/base.py", line 1146, in _execute_context
    context)
  File "/software/mb/el6.3/Conda/lib/python2.7/site-packages/sqlalchemy/engine/base.py", line 1341, in _handle_dbapi_exception
    exc_info
  File "/software/mb/el6.3/Conda/lib/python2.7/site-packages/sqlalchemy/util/compat.py", line 200, in raise_from_cause
    reraise(type(exception), exception, tb=exc_tb, cause=cause)
  File "/software/mb/el6.3/Conda/lib/python2.7/site-packages/sqlalchemy/engine/base.py", line 1139, in _execute_context
    context)
  File "/software/mb/el6.3/Conda/lib/python2.7/site-packages/sqlalchemy/engine/default.py", line 450, in do_execute
    cursor.execute(statement, parameters)
sqlalchemy.exc.OperationalError: (sqlite3.OperationalError) database is locked [SQL: u'UPDATE hic SET "MEMORY"=? WHERE hic."SAMPLE_ID" = ?'] [parameters: ('100G', '3915492f5_daf5eda58')]
Traceback (most recent call last):
  File "/users/project/4DGenome/utils/io_metadata.py", line 100, in <module>
    tab.upsert(new_data, ['SAMPLE_ID'])
  File "/software/mb/el6.3/Conda/lib/python2.7/site-packages/dataset/persistence/table.py", line 171, in upsert
    row_count = self.update(row, keys, ensure=ensure, types=types)
  File "/software/mb/el6.3/Conda/lib/python2.7/site-packages/dataset/persistence/table.py", line 144, in update
    rp = self.database.executable.execute(stmt)
  File "/software/mb/el6.3/Conda/lib/python2.7/site-packages/sqlalchemy/engine/base.py", line 1991, in execute
    return connection.execute(statement, *multiparams, **params)
  File "/software/mb/el6.3/Conda/lib/python2.7/site-packages/sqlalchemy/engine/base.py", line 914, in execute
    return meth(self, multiparams, params)
  File "/software/mb/el6.3/Conda/lib/python2.7/site-packages/sqlalchemy/sql/elements.py", line 323, in _execute_on_connection
    return connection._execute_clauseelement(self, multiparams, params)
  File "/software/mb/el6.3/Conda/lib/python2.7/site-packages/sqlalchemy/engine/base.py", line 1010, in _execute_clauseelement
    compiled_sql, distilled_params
  File "/software/mb/el6.3/Conda/lib/python2.7/site-packages/sqlalchemy/engine/base.py", line 1146, in _execute_context
    context)
  File "/software/mb/el6.3/Conda/lib/python2.7/site-packages/sqlalchemy/engine/base.py", line 1341, in _handle_dbapi_exception
    exc_info
  File "/software/mb/el6.3/Conda/lib/python2.7/site-packages/sqlalchemy/util/compat.py", line 200, in raise_from_cause
    reraise(type(exception), exception, tb=exc_tb, cause=cause)
  File "/software/mb/el6.3/Conda/lib/python2.7/site-packages/sqlalchemy/engine/base.py", line 1139, in _execute_context
    context)
  File "/software/mb/el6.3/Conda/lib/python2.7/site-packages/sqlalchemy/engine/default.py", line 450, in do_execute
    cursor.execute(statement, parameters)
sqlalchemy.exc.OperationalError: (sqlite3.OperationalError) database is locked [SQL: u'UPDATE hic SET "SLOTS"=? WHERE hic."SAMPLE_ID" = ?'] [parameters: ('10', '3915492f5_daf5eda58')]
Traceback (most recent call last):
  File "/users/project/4DGenome/utils/io_metadata.py", line 100, in <module>
    tab.upsert(new_data, ['SAMPLE_ID'])
  File "/software/mb/el6.3/Conda/lib/python2.7/site-packages/dataset/persistence/table.py", line 171, in upsert
    row_count = self.update(row, keys, ensure=ensure, types=types)
  File "/software/mb/el6.3/Conda/lib/python2.7/site-packages/dataset/persistence/table.py", line 144, in update
    rp = self.database.executable.execute(stmt)
  File "/software/mb/el6.3/Conda/lib/python2.7/site-packages/sqlalchemy/engine/base.py", line 1991, in execute
    return connection.execute(statement, *multiparams, **params)
  File "/software/mb/el6.3/Conda/lib/python2.7/site-packages/sqlalchemy/engine/base.py", line 914, in execute
    return meth(self, multiparams, params)
  File "/software/mb/el6.3/Conda/lib/python2.7/site-packages/sqlalchemy/sql/elements.py", line 323, in _execute_on_connection
    return connection._execute_clauseelement(self, multiparams, params)
  File "/software/mb/el6.3/Conda/lib/python2.7/site-packages/sqlalchemy/engine/base.py", line 1010, in _execute_clauseelement
    compiled_sql, distilled_params
  File "/software/mb/el6.3/Conda/lib/python2.7/site-packages/sqlalchemy/engine/base.py", line 1146, in _execute_context
    context)
  File "/software/mb/el6.3/Conda/lib/python2.7/site-packages/sqlalchemy/engine/base.py", line 1341, in _handle_dbapi_exception
    exc_info
  File "/software/mb/el6.3/Conda/lib/python2.7/site-packages/sqlalchemy/util/compat.py", line 200, in raise_from_cause
    reraise(type(exception), exception, tb=exc_tb, cause=cause)
  File "/software/mb/el6.3/Conda/lib/python2.7/site-packages/sqlalchemy/engine/base.py", line 1139, in _execute_context
    context)
  File "/software/mb/el6.3/Conda/lib/python2.7/site-packages/sqlalchemy/engine/default.py", line 450, in do_execute
    cursor.execute(statement, parameters)
sqlalchemy.exc.OperationalError: (sqlite3.OperationalError) database is locked [SQL: u'UPDATE hic SET "ASSEMBLY_VERSION"=? WHERE hic."SAMPLE_ID" = ?'] [parameters: ('hg38_mmtv', '3915492f5_daf5eda58')]
Traceback (most recent call last):
  File "/users/project/4DGenome/utils/io_metadata.py", line 100, in <module>
    tab.upsert(new_data, ['SAMPLE_ID'])
  File "/software/mb/el6.3/Conda/lib/python2.7/site-packages/dataset/persistence/table.py", line 171, in upsert
    row_count = self.update(row, keys, ensure=ensure, types=types)
  File "/software/mb/el6.3/Conda/lib/python2.7/site-packages/dataset/persistence/table.py", line 144, in update
    rp = self.database.executable.execute(stmt)
  File "/software/mb/el6.3/Conda/lib/python2.7/site-packages/sqlalchemy/engine/base.py", line 1991, in execute
    return connection.execute(statement, *multiparams, **params)
  File "/software/mb/el6.3/Conda/lib/python2.7/site-packages/sqlalchemy/engine/base.py", line 914, in execute
    return meth(self, multiparams, params)
  File "/software/mb/el6.3/Conda/lib/python2.7/site-packages/sqlalchemy/sql/elements.py", line 323, in _execute_on_connection
    return connection._execute_clauseelement(self, multiparams, params)
  File "/software/mb/el6.3/Conda/lib/python2.7/site-packages/sqlalchemy/engine/base.py", line 1010, in _execute_clauseelement
    compiled_sql, distilled_params
  File "/software/mb/el6.3/Conda/lib/python2.7/site-packages/sqlalchemy/engine/base.py", line 1146, in _execute_context
    context)
  File "/software/mb/el6.3/Conda/lib/python2.7/site-packages/sqlalchemy/engine/base.py", line 1341, in _handle_dbapi_exception
    exc_info
  File "/software/mb/el6.3/Conda/lib/python2.7/site-packages/sqlalchemy/util/compat.py", line 200, in raise_from_cause
    reraise(type(exception), exception, tb=exc_tb, cause=cause)
  File "/software/mb/el6.3/Conda/lib/python2.7/site-packages/sqlalchemy/engine/base.py", line 1139, in _execute_context
    context)
  File "/software/mb/el6.3/Conda/lib/python2.7/site-packages/sqlalchemy/engine/default.py", line 450, in do_execute
    cursor.execute(statement, parameters)
sqlalchemy.exc.OperationalError: (sqlite3.OperationalError) database is locked [SQL: u'UPDATE hic SET "JOB_NAME"=? WHERE hic."SAMPLE_ID" = ?'] [parameters: ('hic-16.05', '3915492f5_daf5eda58')]
Traceback (most recent call last):
  File "/users/project/4DGenome/utils/io_metadata.py", line 107, in <module>
    tab.upsert(new_data, ['JOB_ID'])
  File "/software/mb/el6.3/Conda/lib/python2.7/site-packages/dataset/persistence/table.py", line 171, in upsert
    row_count = self.update(row, keys, ensure=ensure, types=types)
  File "/software/mb/el6.3/Conda/lib/python2.7/site-packages/dataset/persistence/table.py", line 144, in update
    rp = self.database.executable.execute(stmt)
  File "/software/mb/el6.3/Conda/lib/python2.7/site-packages/sqlalchemy/engine/base.py", line 1991, in execute
    return connection.execute(statement, *multiparams, **params)
  File "/software/mb/el6.3/Conda/lib/python2.7/site-packages/sqlalchemy/engine/base.py", line 914, in execute
    return meth(self, multiparams, params)
  File "/software/mb/el6.3/Conda/lib/python2.7/site-packages/sqlalchemy/sql/elements.py", line 323, in _execute_on_connection
    return connection._execute_clauseelement(self, multiparams, params)
  File "/software/mb/el6.3/Conda/lib/python2.7/site-packages/sqlalchemy/engine/base.py", line 1010, in _execute_clauseelement
    compiled_sql, distilled_params
  File "/software/mb/el6.3/Conda/lib/python2.7/site-packages/sqlalchemy/engine/base.py", line 1146, in _execute_context
    context)
  File "/software/mb/el6.3/Conda/lib/python2.7/site-packages/sqlalchemy/engine/base.py", line 1341, in _handle_dbapi_exception
    exc_info
  File "/software/mb/el6.3/Conda/lib/python2.7/site-packages/sqlalchemy/util/compat.py", line 200, in raise_from_cause
    reraise(type(exception), exception, tb=exc_tb, cause=cause)
  File "/software/mb/el6.3/Conda/lib/python2.7/site-packages/sqlalchemy/engine/base.py", line 1139, in _execute_context
    context)
  File "/software/mb/el6.3/Conda/lib/python2.7/site-packages/sqlalchemy/engine/default.py", line 450, in do_execute
    cursor.execute(statement, parameters)
sqlalchemy.exc.OperationalError: (sqlite3.OperationalError) database is locked [SQL: u'UPDATE jobs SET "PATH_JOB_FILE"=? WHERE jobs."JOB_ID" = ?'] [parameters: ('/users/project/4DGenome/pipelines/hic-16.05/job_cmd/job_3915492f5_daf5eda58_2016_06_02_full_hic-16.05.sh', '3915492f5_daf5eda58;2016-06-02-18-00')]
Traceback (most recent call last):
  File "/users/project/4DGenome/utils/io_metadata.py", line 100, in <module>
    tab.upsert(new_data, ['SAMPLE_ID'])
  File "/software/mb/el6.3/Conda/lib/python2.7/site-packages/dataset/persistence/table.py", line 171, in upsert
    row_count = self.update(row, keys, ensure=ensure, types=types)
  File "/software/mb/el6.3/Conda/lib/python2.7/site-packages/dataset/persistence/table.py", line 144, in update
    rp = self.database.executable.execute(stmt)
  File "/software/mb/el6.3/Conda/lib/python2.7/site-packages/sqlalchemy/engine/base.py", line 1991, in execute
    return connection.execute(statement, *multiparams, **params)
  File "/software/mb/el6.3/Conda/lib/python2.7/site-packages/sqlalchemy/engine/base.py", line 914, in execute
    return meth(self, multiparams, params)
  File "/software/mb/el6.3/Conda/lib/python2.7/site-packages/sqlalchemy/sql/elements.py", line 323, in _execute_on_connection
    return connection._execute_clauseelement(self, multiparams, params)
  File "/software/mb/el6.3/Conda/lib/python2.7/site-packages/sqlalchemy/engine/base.py", line 1010, in _execute_clauseelement
    compiled_sql, distilled_params
  File "/software/mb/el6.3/Conda/lib/python2.7/site-packages/sqlalchemy/engine/base.py", line 1146, in _execute_context
    context)
  File "/software/mb/el6.3/Conda/lib/python2.7/site-packages/sqlalchemy/engine/base.py", line 1341, in _handle_dbapi_exception
    exc_info
  File "/software/mb/el6.3/Conda/lib/python2.7/site-packages/sqlalchemy/util/compat.py", line 200, in raise_from_cause
    reraise(type(exception), exception, tb=exc_tb, cause=cause)
  File "/software/mb/el6.3/Conda/lib/python2.7/site-packages/sqlalchemy/engine/base.py", line 1139, in _execute_context
    context)
  File "/software/mb/el6.3/Conda/lib/python2.7/site-packages/sqlalchemy/engine/default.py", line 450, in do_execute
    cursor.execute(statement, parameters)
sqlalchemy.exc.OperationalError: (sqlite3.OperationalError) database is locked [SQL: u'UPDATE hic SET "TADBIT_AND_DEPENDENCIES_VERSIONS"=? WHERE hic."SAMPLE_ID" = ?'] [parameters: ('TADbit:0.1_alpha.726;Machine:2.6.32-504.23.4.el6.x86_64x86_64GNU/Linux;IMP:2.5.0(randomseedindexedat1=1791095845);MCL:14-137;gem-mapper:Notfound;gemtools:Notfound;matplotlib:1.5.1;numpy:1.10.4;scipy:0.17.0', '3915492f5_daf5eda58')]

INFO 	2016-06-02 18:02:43 	[preliminary_checks] 	3915492f5_daf5eda58 found in /users/project/4DGenome/data/4DGenome_metadata.db
INFO 	2016-06-02 18:05:11 	[preliminary_checks] 	paths to read1 and read2 saved to metadata database
INFO 	2016-06-02 18:05:13 	[preliminary_checks] 	Sequencing index added as part of the metadata agrees with that observed in the FASTQ file
INFO 	2016-06-02 18:05:14 	[preliminary_checks] 	read length added as part of the metadata agrees with that observed in the FASTQ file
INFO 	2016-06-02 18:05:14 	[preliminary_checks] 	genome reference FASTA file found at /users/GR/mb/jquilez/assemblies/homo_sapiens/hg38_mmtv/ucsc/hg38_mmtv_chr1-22XYM.fa
INFO 	2016-06-02 18:05:31 	[preliminary_checks] 	paths to reference FASTA saved to metadata database
TIME 	2016-06-02 18:05:31 	[preliminary_checks] 	step time for completion (seconds) = 170

INFO 	2016-06-02 18:05:33 	[raw_fastqs_quality_plots] 	restriction enzyme = DpnII
INFO 	2016-06-02 18:05:33 	[raw_fastqs_quality_plots] 	a subset of 100000 reds will be used to generate the quality plots
INFO 	2016-06-02 18:05:33 	[raw_fastqs_quality_plots] 	making quality plots of the raw FASTQ files... plots saved at /users/project/4DGenome_no_backup/data/hic/samples/3915492f5_daf5eda58/plots/hg38_mmtv/raw_fastqs_quality_plots
INFO 	2016-06-02 18:05:51 	[raw_fastqs_quality_plots] 	percentages of dangling ends and ligated sites in read1 and read2 saved to metadata database
TIME 	2016-06-02 18:05:51 	[raw_fastqs_quality_plots] 	step time for completion (seconds) = 18

INFO 	2016-06-02 18:05:53 	[trim_reads_trimmomatic] 	sequencing type = PE
INFO 	2016-06-02 18:05:53 	[trim_reads_trimmomatic] 	trimming TruSeq3 adapter sequences for HiSeq, NextSeq or HiSeq
INFO 	2016-06-02 18:05:53 	[trim_reads_trimmomatic] 	trimming low-quality reads ends using trimmomatic's recommended practices
INFO 	2016-06-02 18:26:25 	[trim_reads_trimmomatic] 	parse step log to extract generated metadata
INFO 	2016-06-02 18:26:25 	[trim_reads_trimmomatic] 	reads after trimming = 41254237
INFO 	2016-06-02 18:26:48 	[trim_reads_trimmomatic] 	trimmomatic parameters and numbe of trimmed reads added to metadata
INFO 	2016-06-02 18:26:48 	[trim_reads_trimmomatic] 	trimmed reads are in /users/project/4DGenome_no_backup/data/hic/samples/3915492f5_daf5eda58/fastqs_processed/trimmomatic/paired_end
INFO 	2016-06-02 18:26:48 	[trim_reads_trimmomatic] 	unpaired reads are deleted
TIME 	2016-06-02 18:26:48 	[trim_reads_trimmomatic] 	step time for completion (seconds) = 1255

INFO 	2016-06-02 18:26:50 	[align_and_merge] 	species = Homo_sapiens
INFO 	2016-06-02 18:26:50 	[align_and_merge] 	assembly version = hg38_mmtv
INFO 	2016-06-02 18:26:50 	[align_and_merge] 	restriction enzyme = DpnII
INFO 	2016-06-02 18:26:50 	[align_and_merge] 	read length = 76
INFO 	2016-06-02 18:26:50 	[align_and_merge] 	genome reference FASTA file found at /users/GR/mb/jquilez/assemblies/homo_sapiens/hg38_mmtv/ucsc/hg38_mmtv_chr1-22XYM.fa
INFO 	2016-06-02 18:26:50 	[align_and_merge] 	mapping, processing reads according to restriction enzyme fragments and merging aligments for read1 and read2...
INFO 	2016-06-02 20:40:58 	[align_and_merge] 	output saved in /users/project/4DGenome_no_backup/data/hic/samples/3915492f5_daf5eda58/logs/hg38_mmtv/3915492f5_daf5eda58_align_and_merge_paired_end.log
TIME 	2016-06-02 20:41:45 	[align_and_merge] 	step time for completion (seconds) = 8095

INFO 	2016-06-02 20:41:50 	[post_mapping_statistics] 	generating post mapping descriptive statistics plots...
INFO 	2016-06-02 20:53:33 	[post_mapping_statistics] 	fraction of reads mapped read1 = 0.981215917289
INFO 	2016-06-02 20:53:33 	[post_mapping_statistics] 	fraction of reads mapped read2 = 0.830796046476
INFO 	2016-06-02 20:53:33 	[post_mapping_statistics] 	number of pairs in which both read1 and read2 are mapped = 25369913
INFO 	2016-06-02 20:53:33 	[post_mapping_statistics] 	counts-to-distance slope = -1.22673633239
TIME 	2016-06-02 20:53:51 	[post_mapping_statistics] 	step time for completion (seconds) = 722

INFO 	2016-06-02 20:53:57 	[reads_filtering] 	filtering reads based on multiple quality parameters...
INFO 	2016-06-02 20:53:57 	[reads_filtering] 	filtered reads to be used for subsequent analyses are at /users/project/4DGenome_no_backup/data/hic/samples/3915492f5_daf5eda58/results/hg38_mmtv/filtered_reads
INFO 	2016-06-02 20:53:57 	[reads_filtering] 	excluded reads due to dangling ends are at /users/project/4DGenome_no_backup/data/hic/samples/3915492f5_daf5eda58/results/hg38_mmtv/excluded_reads/dangling_ends
INFO 	2016-06-02 20:53:57 	[reads_filtering] 	excluded reads due to self circle are at /users/project/4DGenome_no_backup/data/hic/samples/3915492f5_daf5eda58/results/hg38_mmtv/excluded_reads/self_circle
INFO 	2016-06-02 20:53:57 	[reads_filtering] 	summary of excluded reads at /users/project/4DGenome_no_backup/data/hic/samples/3915492f5_daf5eda58/results/hg38_mmtv/excluded_reads/summary_excluded_per_filter
INFO 	2016-06-02 21:00:10 	[reads_filtering] 	numbers and fractions of filtered and excluded reads added to the metadata
TIME 	2016-06-02 21:00:28 	[reads_filtering] 	step time for completion (seconds) = 395

INFO 	2016-06-02 21:00:30 	[post_filtering_statistics] 	generating post filtering descriptive statistics plots... saved at /users/project/4DGenome_no_backup/data/hic/samples/3915492f5_daf5eda58/plots/hg38_mmtv/post_filtering_statistics:
INFO 	2016-06-02 21:00:30 	[post_filtering_statistics] 	- filtered reads: sequencing coverage along chromosomes, coverage values and interaction matrix
INFO 	2016-06-02 21:00:30 	[post_filtering_statistics] 	- dangling ends: sequencing coverage along chromosomes and coverage values
INFO 	2016-06-02 21:00:30 	[post_filtering_statistics] 	- self-circle ends: sequencing coverage along chromosomes and coverage values
TIME 	2016-06-02 21:05:52 	[post_filtering_statistics] 	step time for completion (seconds) = 322

INFO 	2016-06-02 21:05:55 	[map_to_bam] 	converting MAP to BAM
[bam_sort_core] merging from 19 files...
TIME 	2016-06-02 21:31:24 	[map_to_bam] 	step time for completion (seconds) = 1529

INFO 	2016-06-02 21:31:27 	[downstream_bam] 	perform several downstream analyses
/usr/share/univage/soldierantcluster/spool/node-hp0308/job_scripts/4412355: line 768: 34801 Segmentation fault      (core dumped) $python $SCRIPTS/tadbit_after_bam.py $ibam $flag_excluded $flag_included $flag_perzero $DOWNSTREAM/${sample_id}_ $slots $resolution_ab $resolution_tad &>$step_log
INFO 	2016-06-02 22:30:29 	[downstream_bam] 	number of TADs = 21
TIME 	2016-06-02 22:30:50 	[downstream_bam] 	step time for completion (seconds) = 3563

INFO 	2016-06-02 22:30:53 	[clean_up] 	deleting the following intermediate files/directories:
INFO 	2016-06-02 22:30:53 	[clean_up] 	/users/project/4DGenome_no_backup/data/hic/samples/3915492f5_daf5eda58/fastqs_processed
INFO 	2016-06-02 22:30:53 	[clean_up] 	/users/project/4DGenome_no_backup/data/hic/samples/3915492f5_daf5eda58/mapped_reads
TIME 	2016-06-02 22:31:00 	[clean_up] 	step time for completion (seconds) = 7


INFO 	2016-06-02 22:31:04 	[pipeline] 	completed successfully
TIME 	2016-06-02 22:31:04 	[pipeline] 	total time for completion (seconds) = 16232

