Traceback (most recent call last):
  File "/usr/lib64/python2.6/logging/handlers.py", line 77, in emit
    self.doRollover()
  File "/usr/lib64/python2.6/logging/handlers.py", line 133, in doRollover
    os.remove(dfn)
OSError: [Errno 2] No such file or directory: '/software/mb/el6.3/python/envs/.virtualenvs/hook.log.1'
Traceback (most recent call last):
  File "/usr/lib64/python2.6/logging/handlers.py", line 76, in emit
    if self.shouldRollover(record):
  File "/usr/lib64/python2.6/logging/handlers.py", line 150, in shouldRollover
    self.stream.seek(0, 2)  #due to non-posix-compliant Windows feature
ValueError: I/O operation on closed file
Traceback (most recent call last):
  File "/usr/lib64/python2.6/logging/handlers.py", line 76, in emit
    if self.shouldRollover(record):
  File "/usr/lib64/python2.6/logging/handlers.py", line 150, in shouldRollover
    self.stream.seek(0, 2)  #due to non-posix-compliant Windows feature
ValueError: I/O operation on closed file
Error in atexit._run_exitfuncs:
Traceback (most recent call last):
  File "/usr/lib64/python2.6/atexit.py", line 24, in _run_exitfuncs
    func(*targs, **kargs)
  File "/usr/lib64/python2.6/logging/__init__.py", line 1524, in shutdown
    h.flush()
  File "/usr/lib64/python2.6/logging/__init__.py", line 770, in flush
    self.stream.flush()
ValueError: I/O operation on closed file
Error in sys.exitfunc:
Traceback (most recent call last):
  File "/usr/lib64/python2.6/atexit.py", line 24, in _run_exitfuncs
    func(*targs, **kargs)
  File "/usr/lib64/python2.6/logging/__init__.py", line 1524, in shutdown
    h.flush()
  File "/usr/lib64/python2.6/logging/__init__.py", line 770, in flush
    self.stream.flush()
ValueError: I/O operation on closed file

INFO 	2016-06-02 18:00:46 	[configuration] 	script to access/write from/to metadata: /users/project/4DGenome/utils/io_metadata.sh
INFO 	2016-06-02 18:00:46 	[configuration] 	metadata database: /users/project/4DGenome/data/4DGenome_metadata.db
INFO 	2016-06-02 18:00:46 	[configuration] 	data for b1913e6c1_db4f304ee will be stored at /users/project/4DGenome_no_backup/data/hic/samples/b1913e6c1_db4f304ee
INFO 	2016-06-02 18:00:46 	[configuration] 	paths to input FASTQ files extracted from the metadata
INFO 	2016-06-02 18:01:17 	[configuration] 	species (Homo_sapiens) and assembly version (hg38_mmtv) extracted from the metadata
Traceback (most recent call last):
  File "/users/project/4DGenome/utils/io_metadata.py", line 100, in <module>
    tab.upsert(new_data, ['SAMPLE_ID'])
  File "/software/mb/el6.3/Conda/lib/python2.7/site-packages/dataset/persistence/table.py", line 171, in upsert
    row_count = self.update(row, keys, ensure=ensure, types=types)
  File "/software/mb/el6.3/Conda/lib/python2.7/site-packages/dataset/persistence/table.py", line 144, in update
    rp = self.database.executable.execute(stmt)
  File "/software/mb/el6.3/Conda/lib/python2.7/site-packages/sqlalchemy/engine/base.py", line 1991, in execute
    return connection.execute(statement, *multiparams, **params)
  File "/software/mb/el6.3/Conda/lib/python2.7/site-packages/sqlalchemy/engine/base.py", line 914, in execute
    return meth(self, multiparams, params)
  File "/software/mb/el6.3/Conda/lib/python2.7/site-packages/sqlalchemy/sql/elements.py", line 323, in _execute_on_connection
    return connection._execute_clauseelement(self, multiparams, params)
  File "/software/mb/el6.3/Conda/lib/python2.7/site-packages/sqlalchemy/engine/base.py", line 1010, in _execute_clauseelement
    compiled_sql, distilled_params
  File "/software/mb/el6.3/Conda/lib/python2.7/site-packages/sqlalchemy/engine/base.py", line 1146, in _execute_context
    context)
  File "/software/mb/el6.3/Conda/lib/python2.7/site-packages/sqlalchemy/engine/base.py", line 1341, in _handle_dbapi_exception
    exc_info
  File "/software/mb/el6.3/Conda/lib/python2.7/site-packages/sqlalchemy/util/compat.py", line 200, in raise_from_cause
    reraise(type(exception), exception, tb=exc_tb, cause=cause)
  File "/software/mb/el6.3/Conda/lib/python2.7/site-packages/sqlalchemy/engine/base.py", line 1139, in _execute_context
    context)
  File "/software/mb/el6.3/Conda/lib/python2.7/site-packages/sqlalchemy/engine/default.py", line 450, in do_execute
    cursor.execute(statement, parameters)
sqlalchemy.exc.OperationalError: (sqlite3.OperationalError) database is locked [SQL: u'UPDATE hic SET "QUEUE"=? WHERE hic."SAMPLE_ID" = ?'] [parameters: ('long-sl65', 'b1913e6c1_db4f304ee')]
Traceback (most recent call last):
  File "/users/project/4DGenome/utils/io_metadata.py", line 100, in <module>
    tab.upsert(new_data, ['SAMPLE_ID'])
  File "/software/mb/el6.3/Conda/lib/python2.7/site-packages/dataset/persistence/table.py", line 171, in upsert
    row_count = self.update(row, keys, ensure=ensure, types=types)
  File "/software/mb/el6.3/Conda/lib/python2.7/site-packages/dataset/persistence/table.py", line 144, in update
    rp = self.database.executable.execute(stmt)
  File "/software/mb/el6.3/Conda/lib/python2.7/site-packages/sqlalchemy/engine/base.py", line 1991, in execute
    return connection.execute(statement, *multiparams, **params)
  File "/software/mb/el6.3/Conda/lib/python2.7/site-packages/sqlalchemy/engine/base.py", line 914, in execute
    return meth(self, multiparams, params)
  File "/software/mb/el6.3/Conda/lib/python2.7/site-packages/sqlalchemy/sql/elements.py", line 323, in _execute_on_connection
    return connection._execute_clauseelement(self, multiparams, params)
  File "/software/mb/el6.3/Conda/lib/python2.7/site-packages/sqlalchemy/engine/base.py", line 1010, in _execute_clauseelement
    compiled_sql, distilled_params
  File "/software/mb/el6.3/Conda/lib/python2.7/site-packages/sqlalchemy/engine/base.py", line 1146, in _execute_context
    context)
  File "/software/mb/el6.3/Conda/lib/python2.7/site-packages/sqlalchemy/engine/base.py", line 1341, in _handle_dbapi_exception
    exc_info
  File "/software/mb/el6.3/Conda/lib/python2.7/site-packages/sqlalchemy/util/compat.py", line 200, in raise_from_cause
    reraise(type(exception), exception, tb=exc_tb, cause=cause)
  File "/software/mb/el6.3/Conda/lib/python2.7/site-packages/sqlalchemy/engine/base.py", line 1139, in _execute_context
    context)
  File "/software/mb/el6.3/Conda/lib/python2.7/site-packages/sqlalchemy/engine/default.py", line 450, in do_execute
    cursor.execute(statement, parameters)
sqlalchemy.exc.OperationalError: (sqlite3.OperationalError) database is locked [SQL: u'UPDATE hic SET "MEMORY"=? WHERE hic."SAMPLE_ID" = ?'] [parameters: ('100G', 'b1913e6c1_db4f304ee')]
Traceback (most recent call last):
  File "/users/project/4DGenome/utils/io_metadata.py", line 100, in <module>
    tab.upsert(new_data, ['SAMPLE_ID'])
  File "/software/mb/el6.3/Conda/lib/python2.7/site-packages/dataset/persistence/table.py", line 171, in upsert
    row_count = self.update(row, keys, ensure=ensure, types=types)
  File "/software/mb/el6.3/Conda/lib/python2.7/site-packages/dataset/persistence/table.py", line 144, in update
    rp = self.database.executable.execute(stmt)
  File "/software/mb/el6.3/Conda/lib/python2.7/site-packages/sqlalchemy/engine/base.py", line 1991, in execute
    return connection.execute(statement, *multiparams, **params)
  File "/software/mb/el6.3/Conda/lib/python2.7/site-packages/sqlalchemy/engine/base.py", line 914, in execute
    return meth(self, multiparams, params)
  File "/software/mb/el6.3/Conda/lib/python2.7/site-packages/sqlalchemy/sql/elements.py", line 323, in _execute_on_connection
    return connection._execute_clauseelement(self, multiparams, params)
  File "/software/mb/el6.3/Conda/lib/python2.7/site-packages/sqlalchemy/engine/base.py", line 1010, in _execute_clauseelement
    compiled_sql, distilled_params
  File "/software/mb/el6.3/Conda/lib/python2.7/site-packages/sqlalchemy/engine/base.py", line 1146, in _execute_context
    context)
  File "/software/mb/el6.3/Conda/lib/python2.7/site-packages/sqlalchemy/engine/base.py", line 1341, in _handle_dbapi_exception
    exc_info
  File "/software/mb/el6.3/Conda/lib/python2.7/site-packages/sqlalchemy/util/compat.py", line 200, in raise_from_cause
    reraise(type(exception), exception, tb=exc_tb, cause=cause)
  File "/software/mb/el6.3/Conda/lib/python2.7/site-packages/sqlalchemy/engine/base.py", line 1139, in _execute_context
    context)
  File "/software/mb/el6.3/Conda/lib/python2.7/site-packages/sqlalchemy/engine/default.py", line 450, in do_execute
    cursor.execute(statement, parameters)
sqlalchemy.exc.OperationalError: (sqlite3.OperationalError) database is locked [SQL: u'UPDATE hic SET "MAX_TIME"=? WHERE hic."SAMPLE_ID" = ?'] [parameters: ('100:00:00', 'b1913e6c1_db4f304ee')]
Traceback (most recent call last):
  File "/users/project/4DGenome/utils/io_metadata.py", line 100, in <module>
    tab.upsert(new_data, ['SAMPLE_ID'])
  File "/software/mb/el6.3/Conda/lib/python2.7/site-packages/dataset/persistence/table.py", line 171, in upsert
    row_count = self.update(row, keys, ensure=ensure, types=types)
  File "/software/mb/el6.3/Conda/lib/python2.7/site-packages/dataset/persistence/table.py", line 144, in update
    rp = self.database.executable.execute(stmt)
  File "/software/mb/el6.3/Conda/lib/python2.7/site-packages/sqlalchemy/engine/base.py", line 1991, in execute
    return connection.execute(statement, *multiparams, **params)
  File "/software/mb/el6.3/Conda/lib/python2.7/site-packages/sqlalchemy/engine/base.py", line 914, in execute
    return meth(self, multiparams, params)
  File "/software/mb/el6.3/Conda/lib/python2.7/site-packages/sqlalchemy/sql/elements.py", line 323, in _execute_on_connection
    return connection._execute_clauseelement(self, multiparams, params)
  File "/software/mb/el6.3/Conda/lib/python2.7/site-packages/sqlalchemy/engine/base.py", line 1010, in _execute_clauseelement
    compiled_sql, distilled_params
  File "/software/mb/el6.3/Conda/lib/python2.7/site-packages/sqlalchemy/engine/base.py", line 1146, in _execute_context
    context)
  File "/software/mb/el6.3/Conda/lib/python2.7/site-packages/sqlalchemy/engine/base.py", line 1341, in _handle_dbapi_exception
    exc_info
  File "/software/mb/el6.3/Conda/lib/python2.7/site-packages/sqlalchemy/util/compat.py", line 200, in raise_from_cause
    reraise(type(exception), exception, tb=exc_tb, cause=cause)
  File "/software/mb/el6.3/Conda/lib/python2.7/site-packages/sqlalchemy/engine/base.py", line 1139, in _execute_context
    context)
  File "/software/mb/el6.3/Conda/lib/python2.7/site-packages/sqlalchemy/engine/default.py", line 450, in do_execute
    cursor.execute(statement, parameters)
sqlalchemy.exc.OperationalError: (sqlite3.OperationalError) database is locked [SQL: u'UPDATE hic SET "SLOTS"=? WHERE hic."SAMPLE_ID" = ?'] [parameters: ('10', 'b1913e6c1_db4f304ee')]
Traceback (most recent call last):
  File "/users/project/4DGenome/utils/io_metadata.py", line 100, in <module>
    tab.upsert(new_data, ['SAMPLE_ID'])
  File "/software/mb/el6.3/Conda/lib/python2.7/site-packages/dataset/persistence/table.py", line 171, in upsert
    row_count = self.update(row, keys, ensure=ensure, types=types)
  File "/software/mb/el6.3/Conda/lib/python2.7/site-packages/dataset/persistence/table.py", line 144, in update
    rp = self.database.executable.execute(stmt)
  File "/software/mb/el6.3/Conda/lib/python2.7/site-packages/sqlalchemy/engine/base.py", line 1991, in execute
    return connection.execute(statement, *multiparams, **params)
  File "/software/mb/el6.3/Conda/lib/python2.7/site-packages/sqlalchemy/engine/base.py", line 914, in execute
    return meth(self, multiparams, params)
  File "/software/mb/el6.3/Conda/lib/python2.7/site-packages/sqlalchemy/sql/elements.py", line 323, in _execute_on_connection
    return connection._execute_clauseelement(self, multiparams, params)
  File "/software/mb/el6.3/Conda/lib/python2.7/site-packages/sqlalchemy/engine/base.py", line 1010, in _execute_clauseelement
    compiled_sql, distilled_params
  File "/software/mb/el6.3/Conda/lib/python2.7/site-packages/sqlalchemy/engine/base.py", line 1146, in _execute_context
    context)
  File "/software/mb/el6.3/Conda/lib/python2.7/site-packages/sqlalchemy/engine/base.py", line 1341, in _handle_dbapi_exception
    exc_info
  File "/software/mb/el6.3/Conda/lib/python2.7/site-packages/sqlalchemy/util/compat.py", line 200, in raise_from_cause
    reraise(type(exception), exception, tb=exc_tb, cause=cause)
  File "/software/mb/el6.3/Conda/lib/python2.7/site-packages/sqlalchemy/engine/base.py", line 1139, in _execute_context
    context)
  File "/software/mb/el6.3/Conda/lib/python2.7/site-packages/sqlalchemy/engine/default.py", line 450, in do_execute
    cursor.execute(statement, parameters)
sqlalchemy.exc.OperationalError: (sqlite3.OperationalError) database is locked [SQL: u'UPDATE hic SET "PATH_JOB_FILE"=? WHERE hic."SAMPLE_ID" = ?'] [parameters: ('/users/project/4DGenome/pipelines/hic-16.05/job_cmd/job_b1913e6c1_db4f304ee_2016_06_02_full_hic-16.05.sh', 'b1913e6c1_db4f304ee')]
Traceback (most recent call last):
  File "/users/project/4DGenome/utils/io_metadata.py", line 100, in <module>
    tab.upsert(new_data, ['SAMPLE_ID'])
  File "/software/mb/el6.3/Conda/lib/python2.7/site-packages/dataset/persistence/table.py", line 171, in upsert
    row_count = self.update(row, keys, ensure=ensure, types=types)
  File "/software/mb/el6.3/Conda/lib/python2.7/site-packages/dataset/persistence/table.py", line 144, in update
    rp = self.database.executable.execute(stmt)
  File "/software/mb/el6.3/Conda/lib/python2.7/site-packages/sqlalchemy/engine/base.py", line 1991, in execute
    return connection.execute(statement, *multiparams, **params)
  File "/software/mb/el6.3/Conda/lib/python2.7/site-packages/sqlalchemy/engine/base.py", line 914, in execute
    return meth(self, multiparams, params)
  File "/software/mb/el6.3/Conda/lib/python2.7/site-packages/sqlalchemy/sql/elements.py", line 323, in _execute_on_connection
    return connection._execute_clauseelement(self, multiparams, params)
  File "/software/mb/el6.3/Conda/lib/python2.7/site-packages/sqlalchemy/engine/base.py", line 1010, in _execute_clauseelement
    compiled_sql, distilled_params
  File "/software/mb/el6.3/Conda/lib/python2.7/site-packages/sqlalchemy/engine/base.py", line 1146, in _execute_context
    context)
  File "/software/mb/el6.3/Conda/lib/python2.7/site-packages/sqlalchemy/engine/base.py", line 1341, in _handle_dbapi_exception
    exc_info
  File "/software/mb/el6.3/Conda/lib/python2.7/site-packages/sqlalchemy/util/compat.py", line 200, in raise_from_cause
    reraise(type(exception), exception, tb=exc_tb, cause=cause)
  File "/software/mb/el6.3/Conda/lib/python2.7/site-packages/sqlalchemy/engine/base.py", line 1139, in _execute_context
    context)
  File "/software/mb/el6.3/Conda/lib/python2.7/site-packages/sqlalchemy/engine/default.py", line 450, in do_execute
    cursor.execute(statement, parameters)
sqlalchemy.exc.OperationalError: (sqlite3.OperationalError) database is locked [SQL: u'UPDATE hic SET "TADBIT_AND_DEPENDENCIES_VERSIONS"=? WHERE hic."SAMPLE_ID" = ?'] [parameters: ('TADbit:0.1_alpha.726;Machine:2.6.32-504.23.4.el6.x86_64x86_64GNU/Linux;IMP:2.5.0(randomseedindexedat1=1791095845);MCL:14-137;gem-mapper:Notfound;gemtools:Notfound;matplotlib:1.5.1;numpy:1.10.4;scipy:0.17.0', 'b1913e6c1_db4f304ee')]
Traceback (most recent call last):
  File "/users/project/4DGenome/utils/io_metadata.py", line 100, in <module>
    tab.upsert(new_data, ['SAMPLE_ID'])
  File "/software/mb/el6.3/Conda/lib/python2.7/site-packages/dataset/persistence/table.py", line 171, in upsert
    row_count = self.update(row, keys, ensure=ensure, types=types)
  File "/software/mb/el6.3/Conda/lib/python2.7/site-packages/dataset/persistence/table.py", line 144, in update
    rp = self.database.executable.execute(stmt)
  File "/software/mb/el6.3/Conda/lib/python2.7/site-packages/sqlalchemy/engine/base.py", line 1991, in execute
    return connection.execute(statement, *multiparams, **params)
  File "/software/mb/el6.3/Conda/lib/python2.7/site-packages/sqlalchemy/engine/base.py", line 914, in execute
    return meth(self, multiparams, params)
  File "/software/mb/el6.3/Conda/lib/python2.7/site-packages/sqlalchemy/sql/elements.py", line 323, in _execute_on_connection
    return connection._execute_clauseelement(self, multiparams, params)
  File "/software/mb/el6.3/Conda/lib/python2.7/site-packages/sqlalchemy/engine/base.py", line 1010, in _execute_clauseelement
    compiled_sql, distilled_params
  File "/software/mb/el6.3/Conda/lib/python2.7/site-packages/sqlalchemy/engine/base.py", line 1146, in _execute_context
    context)
  File "/software/mb/el6.3/Conda/lib/python2.7/site-packages/sqlalchemy/engine/base.py", line 1341, in _handle_dbapi_exception
    exc_info
  File "/software/mb/el6.3/Conda/lib/python2.7/site-packages/sqlalchemy/util/compat.py", line 200, in raise_from_cause
    reraise(type(exception), exception, tb=exc_tb, cause=cause)
  File "/software/mb/el6.3/Conda/lib/python2.7/site-packages/sqlalchemy/engine/base.py", line 1139, in _execute_context
    context)
  File "/software/mb/el6.3/Conda/lib/python2.7/site-packages/sqlalchemy/engine/default.py", line 450, in do_execute
    cursor.execute(statement, parameters)
sqlalchemy.exc.OperationalError: (sqlite3.OperationalError) database is locked [SQL: u'UPDATE hic SET "LAST_RUN_DATE"=? WHERE hic."SAMPLE_ID" = ?'] [parameters: ('2016-06-02-18-00', 'b1913e6c1_db4f304ee')]

INFO 	2016-06-02 18:02:54 	[preliminary_checks] 	b1913e6c1_db4f304ee found in /users/project/4DGenome/data/4DGenome_metadata.db
INFO 	2016-06-02 18:13:24 	[preliminary_checks] 	paths to read1 and read2 saved to metadata database
INFO 	2016-06-02 18:13:25 	[preliminary_checks] 	Sequencing index added as part of the metadata agrees with that observed in the FASTQ file
WARN 	2016-06-02 18:13:27 	[preliminary_checks] 	read length obtained from the metadata (75 bp) differs from that seen in the FASTQ (76 bp)
WARN 	2016-06-02 18:13:27 	[preliminary_checks] 	the latter will be kept
INFO 	2016-06-02 18:13:28 	[preliminary_checks] 	genome reference FASTA file found at /users/GR/mb/jquilez/assemblies/homo_sapiens/hg38_mmtv/ucsc/hg38_mmtv_chr1-22XYM.fa
INFO 	2016-06-02 18:13:46 	[preliminary_checks] 	paths to reference FASTA saved to metadata database
TIME 	2016-06-02 18:13:46 	[preliminary_checks] 	step time for completion (seconds) = 654

INFO 	2016-06-02 18:13:47 	[raw_fastqs_quality_plots] 	restriction enzyme = DpnII
INFO 	2016-06-02 18:13:47 	[raw_fastqs_quality_plots] 	a subset of 100000 reds will be used to generate the quality plots
INFO 	2016-06-02 18:13:48 	[raw_fastqs_quality_plots] 	making quality plots of the raw FASTQ files... plots saved at /users/project/4DGenome_no_backup/data/hic/samples/b1913e6c1_db4f304ee/plots/hg38_mmtv/raw_fastqs_quality_plots
INFO 	2016-06-02 18:14:06 	[raw_fastqs_quality_plots] 	percentages of dangling ends and ligated sites in read1 and read2 saved to metadata database
TIME 	2016-06-02 18:14:06 	[raw_fastqs_quality_plots] 	step time for completion (seconds) = 19

INFO 	2016-06-02 18:14:08 	[trim_reads_trimmomatic] 	sequencing type = PE
INFO 	2016-06-02 18:14:08 	[trim_reads_trimmomatic] 	trimming TruSeq3 adapter sequences for HiSeq, NextSeq or HiSeq
INFO 	2016-06-02 18:14:08 	[trim_reads_trimmomatic] 	trimming low-quality reads ends using trimmomatic's recommended practices
INFO 	2016-06-02 19:35:57 	[trim_reads_trimmomatic] 	parse step log to extract generated metadata
INFO 	2016-06-02 19:35:57 	[trim_reads_trimmomatic] 	reads after trimming = 160097689
INFO 	2016-06-02 19:36:17 	[trim_reads_trimmomatic] 	trimmomatic parameters and numbe of trimmed reads added to metadata
INFO 	2016-06-02 19:36:17 	[trim_reads_trimmomatic] 	trimmed reads are in /users/project/4DGenome_no_backup/data/hic/samples/b1913e6c1_db4f304ee/fastqs_processed/trimmomatic/paired_end
INFO 	2016-06-02 19:36:17 	[trim_reads_trimmomatic] 	unpaired reads are deleted
TIME 	2016-06-02 19:36:17 	[trim_reads_trimmomatic] 	step time for completion (seconds) = 4929

INFO 	2016-06-02 19:36:19 	[align_and_merge] 	species = Homo_sapiens
INFO 	2016-06-02 19:36:19 	[align_and_merge] 	assembly version = hg38_mmtv
INFO 	2016-06-02 19:36:19 	[align_and_merge] 	restriction enzyme = DpnII
INFO 	2016-06-02 19:36:19 	[align_and_merge] 	read length = 75
INFO 	2016-06-02 19:36:19 	[align_and_merge] 	genome reference FASTA file found at /users/GR/mb/jquilez/assemblies/homo_sapiens/hg38_mmtv/ucsc/hg38_mmtv_chr1-22XYM.fa
INFO 	2016-06-02 19:36:19 	[align_and_merge] 	mapping, processing reads according to restriction enzyme fragments and merging aligments for read1 and read2...
INFO 	2016-06-03 04:39:22 	[align_and_merge] 	output saved in /users/project/4DGenome_no_backup/data/hic/samples/b1913e6c1_db4f304ee/logs/hg38_mmtv/b1913e6c1_db4f304ee_align_and_merge_paired_end.log
TIME 	2016-06-03 04:42:38 	[align_and_merge] 	step time for completion (seconds) = 32779

INFO 	2016-06-03 04:42:55 	[post_mapping_statistics] 	generating post mapping descriptive statistics plots...
INFO 	2016-06-03 05:22:20 	[post_mapping_statistics] 	fraction of reads mapped read1 = 1.01996723388
INFO 	2016-06-03 05:22:20 	[post_mapping_statistics] 	fraction of reads mapped read2 = 0.902380652103
INFO 	2016-06-03 05:22:20 	[post_mapping_statistics] 	number of pairs in which both read1 and read2 are mapped = 108858162
INFO 	2016-06-03 05:22:20 	[post_mapping_statistics] 	counts-to-distance slope = -1.2244510083
TIME 	2016-06-03 05:22:29 	[post_mapping_statistics] 	step time for completion (seconds) = 2374

INFO 	2016-06-03 05:22:52 	[reads_filtering] 	filtering reads based on multiple quality parameters...
INFO 	2016-06-03 05:22:52 	[reads_filtering] 	filtered reads to be used for subsequent analyses are at /users/project/4DGenome_no_backup/data/hic/samples/b1913e6c1_db4f304ee/results/hg38_mmtv/filtered_reads
INFO 	2016-06-03 05:22:52 	[reads_filtering] 	excluded reads due to dangling ends are at /users/project/4DGenome_no_backup/data/hic/samples/b1913e6c1_db4f304ee/results/hg38_mmtv/excluded_reads/dangling_ends
INFO 	2016-06-03 05:22:52 	[reads_filtering] 	excluded reads due to self circle are at /users/project/4DGenome_no_backup/data/hic/samples/b1913e6c1_db4f304ee/results/hg38_mmtv/excluded_reads/self_circle
INFO 	2016-06-03 05:22:52 	[reads_filtering] 	summary of excluded reads at /users/project/4DGenome_no_backup/data/hic/samples/b1913e6c1_db4f304ee/results/hg38_mmtv/excluded_reads/summary_excluded_per_filter
INFO 	2016-06-03 05:44:33 	[reads_filtering] 	numbers and fractions of filtered and excluded reads added to the metadata
TIME 	2016-06-03 05:46:30 	[reads_filtering] 	step time for completion (seconds) = 1439

INFO 	2016-06-03 05:46:34 	[post_filtering_statistics] 	generating post filtering descriptive statistics plots... saved at /users/project/4DGenome_no_backup/data/hic/samples/b1913e6c1_db4f304ee/plots/hg38_mmtv/post_filtering_statistics:
INFO 	2016-06-03 05:46:34 	[post_filtering_statistics] 	- filtered reads: sequencing coverage along chromosomes, coverage values and interaction matrix
INFO 	2016-06-03 05:46:34 	[post_filtering_statistics] 	- dangling ends: sequencing coverage along chromosomes and coverage values
INFO 	2016-06-03 05:46:34 	[post_filtering_statistics] 	- self-circle ends: sequencing coverage along chromosomes and coverage values
TIME 	2016-06-03 06:08:59 	[post_filtering_statistics] 	step time for completion (seconds) = 1345

INFO 	2016-06-03 06:09:01 	[map_to_bam] 	converting MAP to BAM
[bam_sort_core] merging from 78 files...
TIME 	2016-06-03 07:58:10 	[map_to_bam] 	step time for completion (seconds) = 6549

INFO 	2016-06-03 07:58:26 	[downstream_bam] 	perform several downstream analyses
INFO 	2016-06-03 14:23:47 	[downstream_bam] 	number of TADs = 3110
TIME 	2016-06-03 14:24:07 	[downstream_bam] 	step time for completion (seconds) = 23141

INFO 	2016-06-03 14:24:09 	[clean_up] 	deleting the following intermediate files/directories:
INFO 	2016-06-03 14:24:09 	[clean_up] 	/users/project/4DGenome_no_backup/data/hic/samples/b1913e6c1_db4f304ee/fastqs_processed
INFO 	2016-06-03 14:24:09 	[clean_up] 	/users/project/4DGenome_no_backup/data/hic/samples/b1913e6c1_db4f304ee/mapped_reads
TIME 	2016-06-03 14:24:09 	[clean_up] 	step time for completion (seconds) = 0


INFO 	2016-06-03 14:24:11 	[pipeline] 	completed successfully
TIME 	2016-06-03 14:24:11 	[pipeline] 	total time for completion (seconds) = 73405

