Traceback (most recent call last):
  File "/usr/lib64/python2.6/logging/handlers.py", line 77, in emit
    self.doRollover()
  File "/usr/lib64/python2.6/logging/handlers.py", line 133, in doRollover
    os.remove(dfn)
OSError: [Errno 2] No such file or directory: '/software/mb/el6.3/python/envs/.virtualenvs/hook.log.1'
Traceback (most recent call last):
  File "/usr/lib64/python2.6/logging/handlers.py", line 76, in emit
    if self.shouldRollover(record):
  File "/usr/lib64/python2.6/logging/handlers.py", line 150, in shouldRollover
    self.stream.seek(0, 2)  #due to non-posix-compliant Windows feature
ValueError: I/O operation on closed file
Error in atexit._run_exitfuncs:
Traceback (most recent call last):
  File "/usr/lib64/python2.6/atexit.py", line 24, in _run_exitfuncs
    func(*targs, **kargs)
  File "/usr/lib64/python2.6/logging/__init__.py", line 1524, in shutdown
    h.flush()
  File "/usr/lib64/python2.6/logging/__init__.py", line 770, in flush
    self.stream.flush()
ValueError: I/O operation on closed file
Error in sys.exitfunc:
Traceback (most recent call last):
  File "/usr/lib64/python2.6/atexit.py", line 24, in _run_exitfuncs
    func(*targs, **kargs)
  File "/usr/lib64/python2.6/logging/__init__.py", line 1524, in shutdown
    h.flush()
  File "/usr/lib64/python2.6/logging/__init__.py", line 770, in flush
    self.stream.flush()
ValueError: I/O operation on closed file

INFO 	2016-06-02 18:00:32 	[configuration] 	script to access/write from/to metadata: /users/project/4DGenome/utils/io_metadata.sh
INFO 	2016-06-02 18:00:32 	[configuration] 	metadata database: /users/project/4DGenome/data/4DGenome_metadata.db
INFO 	2016-06-02 18:00:32 	[configuration] 	data for dc3a1e069_ec92aa0bb will be stored at /users/project/4DGenome_no_backup/data/hic/samples/dc3a1e069_ec92aa0bb
INFO 	2016-06-02 18:00:32 	[configuration] 	paths to input FASTQ files extracted from the metadata
INFO 	2016-06-02 18:01:01 	[configuration] 	species (Homo_sapiens) and assembly version (hg38_mmtv) extracted from the metadata
Traceback (most recent call last):
  File "/users/project/4DGenome/utils/io_metadata.py", line 107, in <module>
    tab.upsert(new_data, ['JOB_ID'])
  File "/software/mb/el6.3/Conda/lib/python2.7/site-packages/dataset/persistence/table.py", line 171, in upsert
    row_count = self.update(row, keys, ensure=ensure, types=types)
  File "/software/mb/el6.3/Conda/lib/python2.7/site-packages/dataset/persistence/table.py", line 144, in update
    rp = self.database.executable.execute(stmt)
  File "/software/mb/el6.3/Conda/lib/python2.7/site-packages/sqlalchemy/engine/base.py", line 1991, in execute
    return connection.execute(statement, *multiparams, **params)
  File "/software/mb/el6.3/Conda/lib/python2.7/site-packages/sqlalchemy/engine/base.py", line 914, in execute
    return meth(self, multiparams, params)
  File "/software/mb/el6.3/Conda/lib/python2.7/site-packages/sqlalchemy/sql/elements.py", line 323, in _execute_on_connection
    return connection._execute_clauseelement(self, multiparams, params)
  File "/software/mb/el6.3/Conda/lib/python2.7/site-packages/sqlalchemy/engine/base.py", line 1010, in _execute_clauseelement
    compiled_sql, distilled_params
  File "/software/mb/el6.3/Conda/lib/python2.7/site-packages/sqlalchemy/engine/base.py", line 1146, in _execute_context
    context)
  File "/software/mb/el6.3/Conda/lib/python2.7/site-packages/sqlalchemy/engine/base.py", line 1341, in _handle_dbapi_exception
    exc_info
  File "/software/mb/el6.3/Conda/lib/python2.7/site-packages/sqlalchemy/util/compat.py", line 200, in raise_from_cause
    reraise(type(exception), exception, tb=exc_tb, cause=cause)
  File "/software/mb/el6.3/Conda/lib/python2.7/site-packages/sqlalchemy/engine/base.py", line 1139, in _execute_context
    context)
  File "/software/mb/el6.3/Conda/lib/python2.7/site-packages/sqlalchemy/engine/default.py", line 450, in do_execute
    cursor.execute(statement, parameters)
sqlalchemy.exc.OperationalError: (sqlite3.OperationalError) database is locked [SQL: u'UPDATE jobs SET "QUEUE"=? WHERE jobs."JOB_ID" = ?'] [parameters: ('long-sl65', 'dc3a1e069_ec92aa0bb;2016-06-02-18-00')]
Traceback (most recent call last):
  File "/users/project/4DGenome/utils/io_metadata.py", line 100, in <module>
    tab.upsert(new_data, ['SAMPLE_ID'])
  File "/software/mb/el6.3/Conda/lib/python2.7/site-packages/dataset/persistence/table.py", line 171, in upsert
    row_count = self.update(row, keys, ensure=ensure, types=types)
  File "/software/mb/el6.3/Conda/lib/python2.7/site-packages/dataset/persistence/table.py", line 144, in update
    rp = self.database.executable.execute(stmt)
  File "/software/mb/el6.3/Conda/lib/python2.7/site-packages/sqlalchemy/engine/base.py", line 1991, in execute
    return connection.execute(statement, *multiparams, **params)
  File "/software/mb/el6.3/Conda/lib/python2.7/site-packages/sqlalchemy/engine/base.py", line 914, in execute
    return meth(self, multiparams, params)
  File "/software/mb/el6.3/Conda/lib/python2.7/site-packages/sqlalchemy/sql/elements.py", line 323, in _execute_on_connection
    return connection._execute_clauseelement(self, multiparams, params)
  File "/software/mb/el6.3/Conda/lib/python2.7/site-packages/sqlalchemy/engine/base.py", line 1010, in _execute_clauseelement
    compiled_sql, distilled_params
  File "/software/mb/el6.3/Conda/lib/python2.7/site-packages/sqlalchemy/engine/base.py", line 1146, in _execute_context
    context)
  File "/software/mb/el6.3/Conda/lib/python2.7/site-packages/sqlalchemy/engine/base.py", line 1341, in _handle_dbapi_exception
    exc_info
  File "/software/mb/el6.3/Conda/lib/python2.7/site-packages/sqlalchemy/util/compat.py", line 200, in raise_from_cause
    reraise(type(exception), exception, tb=exc_tb, cause=cause)
  File "/software/mb/el6.3/Conda/lib/python2.7/site-packages/sqlalchemy/engine/base.py", line 1139, in _execute_context
    context)
  File "/software/mb/el6.3/Conda/lib/python2.7/site-packages/sqlalchemy/engine/default.py", line 450, in do_execute
    cursor.execute(statement, parameters)
sqlalchemy.exc.OperationalError: (sqlite3.OperationalError) database is locked [SQL: u'UPDATE hic SET "MEMORY"=? WHERE hic."SAMPLE_ID" = ?'] [parameters: ('100G', 'dc3a1e069_ec92aa0bb')]
Traceback (most recent call last):
  File "/users/project/4DGenome/utils/io_metadata.py", line 100, in <module>
    tab.upsert(new_data, ['SAMPLE_ID'])
  File "/software/mb/el6.3/Conda/lib/python2.7/site-packages/dataset/persistence/table.py", line 171, in upsert
    row_count = self.update(row, keys, ensure=ensure, types=types)
  File "/software/mb/el6.3/Conda/lib/python2.7/site-packages/dataset/persistence/table.py", line 144, in update
    rp = self.database.executable.execute(stmt)
  File "/software/mb/el6.3/Conda/lib/python2.7/site-packages/sqlalchemy/engine/base.py", line 1991, in execute
    return connection.execute(statement, *multiparams, **params)
  File "/software/mb/el6.3/Conda/lib/python2.7/site-packages/sqlalchemy/engine/base.py", line 914, in execute
    return meth(self, multiparams, params)
  File "/software/mb/el6.3/Conda/lib/python2.7/site-packages/sqlalchemy/sql/elements.py", line 323, in _execute_on_connection
    return connection._execute_clauseelement(self, multiparams, params)
  File "/software/mb/el6.3/Conda/lib/python2.7/site-packages/sqlalchemy/engine/base.py", line 1010, in _execute_clauseelement
    compiled_sql, distilled_params
  File "/software/mb/el6.3/Conda/lib/python2.7/site-packages/sqlalchemy/engine/base.py", line 1146, in _execute_context
    context)
  File "/software/mb/el6.3/Conda/lib/python2.7/site-packages/sqlalchemy/engine/base.py", line 1341, in _handle_dbapi_exception
    exc_info
  File "/software/mb/el6.3/Conda/lib/python2.7/site-packages/sqlalchemy/util/compat.py", line 200, in raise_from_cause
    reraise(type(exception), exception, tb=exc_tb, cause=cause)
  File "/software/mb/el6.3/Conda/lib/python2.7/site-packages/sqlalchemy/engine/base.py", line 1139, in _execute_context
    context)
  File "/software/mb/el6.3/Conda/lib/python2.7/site-packages/sqlalchemy/engine/default.py", line 450, in do_execute
    cursor.execute(statement, parameters)
sqlalchemy.exc.OperationalError: (sqlite3.OperationalError) database is locked [SQL: u'UPDATE hic SET "MAX_TIME"=? WHERE hic."SAMPLE_ID" = ?'] [parameters: ('100:00:00', 'dc3a1e069_ec92aa0bb')]
Traceback (most recent call last):
  File "/users/project/4DGenome/utils/io_metadata.py", line 107, in <module>
    tab.upsert(new_data, ['JOB_ID'])
  File "/software/mb/el6.3/Conda/lib/python2.7/site-packages/dataset/persistence/table.py", line 171, in upsert
    row_count = self.update(row, keys, ensure=ensure, types=types)
  File "/software/mb/el6.3/Conda/lib/python2.7/site-packages/dataset/persistence/table.py", line 144, in update
    rp = self.database.executable.execute(stmt)
  File "/software/mb/el6.3/Conda/lib/python2.7/site-packages/sqlalchemy/engine/base.py", line 1991, in execute
    return connection.execute(statement, *multiparams, **params)
  File "/software/mb/el6.3/Conda/lib/python2.7/site-packages/sqlalchemy/engine/base.py", line 914, in execute
    return meth(self, multiparams, params)
  File "/software/mb/el6.3/Conda/lib/python2.7/site-packages/sqlalchemy/sql/elements.py", line 323, in _execute_on_connection
    return connection._execute_clauseelement(self, multiparams, params)
  File "/software/mb/el6.3/Conda/lib/python2.7/site-packages/sqlalchemy/engine/base.py", line 1010, in _execute_clauseelement
    compiled_sql, distilled_params
  File "/software/mb/el6.3/Conda/lib/python2.7/site-packages/sqlalchemy/engine/base.py", line 1146, in _execute_context
    context)
  File "/software/mb/el6.3/Conda/lib/python2.7/site-packages/sqlalchemy/engine/base.py", line 1341, in _handle_dbapi_exception
    exc_info
  File "/software/mb/el6.3/Conda/lib/python2.7/site-packages/sqlalchemy/util/compat.py", line 200, in raise_from_cause
    reraise(type(exception), exception, tb=exc_tb, cause=cause)
  File "/software/mb/el6.3/Conda/lib/python2.7/site-packages/sqlalchemy/engine/base.py", line 1139, in _execute_context
    context)
  File "/software/mb/el6.3/Conda/lib/python2.7/site-packages/sqlalchemy/engine/default.py", line 450, in do_execute
    cursor.execute(statement, parameters)
sqlalchemy.exc.OperationalError: (sqlite3.OperationalError) database is locked [SQL: u'UPDATE jobs SET "ASSEMBLY_VERSION"=? WHERE jobs."JOB_ID" = ?'] [parameters: ('hg38_mmtv', 'dc3a1e069_ec92aa0bb;2016-06-02-18-00')]
Traceback (most recent call last):
  File "/users/project/4DGenome/utils/io_metadata.py", line 100, in <module>
    tab.upsert(new_data, ['SAMPLE_ID'])
  File "/software/mb/el6.3/Conda/lib/python2.7/site-packages/dataset/persistence/table.py", line 171, in upsert
    row_count = self.update(row, keys, ensure=ensure, types=types)
  File "/software/mb/el6.3/Conda/lib/python2.7/site-packages/dataset/persistence/table.py", line 144, in update
    rp = self.database.executable.execute(stmt)
  File "/software/mb/el6.3/Conda/lib/python2.7/site-packages/sqlalchemy/engine/base.py", line 1991, in execute
    return connection.execute(statement, *multiparams, **params)
  File "/software/mb/el6.3/Conda/lib/python2.7/site-packages/sqlalchemy/engine/base.py", line 914, in execute
    return meth(self, multiparams, params)
  File "/software/mb/el6.3/Conda/lib/python2.7/site-packages/sqlalchemy/sql/elements.py", line 323, in _execute_on_connection
    return connection._execute_clauseelement(self, multiparams, params)
  File "/software/mb/el6.3/Conda/lib/python2.7/site-packages/sqlalchemy/engine/base.py", line 1010, in _execute_clauseelement
    compiled_sql, distilled_params
  File "/software/mb/el6.3/Conda/lib/python2.7/site-packages/sqlalchemy/engine/base.py", line 1146, in _execute_context
    context)
  File "/software/mb/el6.3/Conda/lib/python2.7/site-packages/sqlalchemy/engine/base.py", line 1341, in _handle_dbapi_exception
    exc_info
  File "/software/mb/el6.3/Conda/lib/python2.7/site-packages/sqlalchemy/util/compat.py", line 200, in raise_from_cause
    reraise(type(exception), exception, tb=exc_tb, cause=cause)
  File "/software/mb/el6.3/Conda/lib/python2.7/site-packages/sqlalchemy/engine/base.py", line 1139, in _execute_context
    context)
  File "/software/mb/el6.3/Conda/lib/python2.7/site-packages/sqlalchemy/engine/default.py", line 450, in do_execute
    cursor.execute(statement, parameters)
sqlalchemy.exc.OperationalError: (sqlite3.OperationalError) database is locked [SQL: u'UPDATE hic SET "JOB_NAME"=? WHERE hic."SAMPLE_ID" = ?'] [parameters: ('hic-16.05', 'dc3a1e069_ec92aa0bb')]
Traceback (most recent call last):
  File "/users/project/4DGenome/utils/io_metadata.py", line 100, in <module>
    tab.upsert(new_data, ['SAMPLE_ID'])
  File "/software/mb/el6.3/Conda/lib/python2.7/site-packages/dataset/persistence/table.py", line 171, in upsert
    row_count = self.update(row, keys, ensure=ensure, types=types)
  File "/software/mb/el6.3/Conda/lib/python2.7/site-packages/dataset/persistence/table.py", line 144, in update
    rp = self.database.executable.execute(stmt)
  File "/software/mb/el6.3/Conda/lib/python2.7/site-packages/sqlalchemy/engine/base.py", line 1991, in execute
    return connection.execute(statement, *multiparams, **params)
  File "/software/mb/el6.3/Conda/lib/python2.7/site-packages/sqlalchemy/engine/base.py", line 914, in execute
    return meth(self, multiparams, params)
  File "/software/mb/el6.3/Conda/lib/python2.7/site-packages/sqlalchemy/sql/elements.py", line 323, in _execute_on_connection
    return connection._execute_clauseelement(self, multiparams, params)
  File "/software/mb/el6.3/Conda/lib/python2.7/site-packages/sqlalchemy/engine/base.py", line 1010, in _execute_clauseelement
    compiled_sql, distilled_params
  File "/software/mb/el6.3/Conda/lib/python2.7/site-packages/sqlalchemy/engine/base.py", line 1146, in _execute_context
    context)
  File "/software/mb/el6.3/Conda/lib/python2.7/site-packages/sqlalchemy/engine/base.py", line 1341, in _handle_dbapi_exception
    exc_info
  File "/software/mb/el6.3/Conda/lib/python2.7/site-packages/sqlalchemy/util/compat.py", line 200, in raise_from_cause
    reraise(type(exception), exception, tb=exc_tb, cause=cause)
  File "/software/mb/el6.3/Conda/lib/python2.7/site-packages/sqlalchemy/engine/base.py", line 1139, in _execute_context
    context)
  File "/software/mb/el6.3/Conda/lib/python2.7/site-packages/sqlalchemy/engine/default.py", line 450, in do_execute
    cursor.execute(statement, parameters)
sqlalchemy.exc.OperationalError: (sqlite3.OperationalError) database is locked [SQL: u'UPDATE hic SET "PATH_JOB_FILE"=? WHERE hic."SAMPLE_ID" = ?'] [parameters: ('/users/project/4DGenome/pipelines/hic-16.05/job_cmd/job_dc3a1e069_ec92aa0bb_2016_06_02_full_hic-16.05.sh', 'dc3a1e069_ec92aa0bb')]
Traceback (most recent call last):
  File "/users/project/4DGenome/utils/io_metadata.py", line 100, in <module>
    tab.upsert(new_data, ['SAMPLE_ID'])
  File "/software/mb/el6.3/Conda/lib/python2.7/site-packages/dataset/persistence/table.py", line 171, in upsert
    row_count = self.update(row, keys, ensure=ensure, types=types)
  File "/software/mb/el6.3/Conda/lib/python2.7/site-packages/dataset/persistence/table.py", line 144, in update
    rp = self.database.executable.execute(stmt)
  File "/software/mb/el6.3/Conda/lib/python2.7/site-packages/sqlalchemy/engine/base.py", line 1991, in execute
    return connection.execute(statement, *multiparams, **params)
  File "/software/mb/el6.3/Conda/lib/python2.7/site-packages/sqlalchemy/engine/base.py", line 914, in execute
    return meth(self, multiparams, params)
  File "/software/mb/el6.3/Conda/lib/python2.7/site-packages/sqlalchemy/sql/elements.py", line 323, in _execute_on_connection
    return connection._execute_clauseelement(self, multiparams, params)
  File "/software/mb/el6.3/Conda/lib/python2.7/site-packages/sqlalchemy/engine/base.py", line 1010, in _execute_clauseelement
    compiled_sql, distilled_params
  File "/software/mb/el6.3/Conda/lib/python2.7/site-packages/sqlalchemy/engine/base.py", line 1146, in _execute_context
    context)
  File "/software/mb/el6.3/Conda/lib/python2.7/site-packages/sqlalchemy/engine/base.py", line 1341, in _handle_dbapi_exception
    exc_info
  File "/software/mb/el6.3/Conda/lib/python2.7/site-packages/sqlalchemy/util/compat.py", line 200, in raise_from_cause
    reraise(type(exception), exception, tb=exc_tb, cause=cause)
  File "/software/mb/el6.3/Conda/lib/python2.7/site-packages/sqlalchemy/engine/base.py", line 1139, in _execute_context
    context)
  File "/software/mb/el6.3/Conda/lib/python2.7/site-packages/sqlalchemy/engine/default.py", line 450, in do_execute
    cursor.execute(statement, parameters)
sqlalchemy.exc.OperationalError: (sqlite3.OperationalError) database is locked [SQL: u'UPDATE hic SET "TADBIT_AND_DEPENDENCIES_VERSIONS"=? WHERE hic."SAMPLE_ID" = ?'] [parameters: ('TADbit:0.1_alpha.726;Machine:2.6.32-504.23.4.el6.x86_64x86_64GNU/Linux;IMP:2.5.0(randomseedindexedat1=1791095845);MCL:14-137;gem-mapper:Notfound;gemtools:Notfound;matplotlib:1.5.1;numpy:1.10.4;scipy:0.17.0', 'dc3a1e069_ec92aa0bb')]

INFO 	2016-06-02 18:02:38 	[preliminary_checks] 	dc3a1e069_ec92aa0bb found in /users/project/4DGenome/data/4DGenome_metadata.db
INFO 	2016-06-02 18:09:41 	[preliminary_checks] 	paths to read1 and read2 saved to metadata database
INFO 	2016-06-02 18:09:43 	[preliminary_checks] 	Sequencing index added as part of the metadata agrees with that observed in the FASTQ file
INFO 	2016-06-02 18:09:44 	[preliminary_checks] 	read length added as part of the metadata agrees with that observed in the FASTQ file
INFO 	2016-06-02 18:09:44 	[preliminary_checks] 	genome reference FASTA file found at /users/GR/mb/jquilez/assemblies/homo_sapiens/hg38_mmtv/ucsc/hg38_mmtv_chr1-22XYM.fa
INFO 	2016-06-02 18:10:20 	[preliminary_checks] 	paths to reference FASTA saved to metadata database
TIME 	2016-06-02 18:10:20 	[preliminary_checks] 	step time for completion (seconds) = 464

INFO 	2016-06-02 18:10:21 	[raw_fastqs_quality_plots] 	restriction enzyme = DpnII
INFO 	2016-06-02 18:10:21 	[raw_fastqs_quality_plots] 	a subset of 100000 reds will be used to generate the quality plots
INFO 	2016-06-02 18:10:21 	[raw_fastqs_quality_plots] 	making quality plots of the raw FASTQ files... plots saved at /users/project/4DGenome_no_backup/data/hic/samples/dc3a1e069_ec92aa0bb/plots/hg38_mmtv/raw_fastqs_quality_plots
INFO 	2016-06-02 18:10:41 	[raw_fastqs_quality_plots] 	percentages of dangling ends and ligated sites in read1 and read2 saved to metadata database
TIME 	2016-06-02 18:10:41 	[raw_fastqs_quality_plots] 	step time for completion (seconds) = 20

INFO 	2016-06-02 18:10:43 	[trim_reads_trimmomatic] 	sequencing type = PE
INFO 	2016-06-02 18:10:43 	[trim_reads_trimmomatic] 	trimming TruSeq3 adapter sequences for HiSeq, NextSeq or HiSeq
INFO 	2016-06-02 18:10:43 	[trim_reads_trimmomatic] 	trimming low-quality reads ends using trimmomatic's recommended practices
INFO 	2016-06-02 18:57:49 	[trim_reads_trimmomatic] 	parse step log to extract generated metadata
INFO 	2016-06-02 18:57:50 	[trim_reads_trimmomatic] 	reads after trimming = 94486696
INFO 	2016-06-02 18:58:19 	[trim_reads_trimmomatic] 	trimmomatic parameters and numbe of trimmed reads added to metadata
INFO 	2016-06-02 18:58:19 	[trim_reads_trimmomatic] 	trimmed reads are in /users/project/4DGenome_no_backup/data/hic/samples/dc3a1e069_ec92aa0bb/fastqs_processed/trimmomatic/paired_end
INFO 	2016-06-02 18:58:19 	[trim_reads_trimmomatic] 	unpaired reads are deleted
TIME 	2016-06-02 18:58:19 	[trim_reads_trimmomatic] 	step time for completion (seconds) = 2856

INFO 	2016-06-02 18:58:21 	[align_and_merge] 	species = Homo_sapiens
INFO 	2016-06-02 18:58:21 	[align_and_merge] 	assembly version = hg38_mmtv
INFO 	2016-06-02 18:58:21 	[align_and_merge] 	restriction enzyme = DpnII
INFO 	2016-06-02 18:58:21 	[align_and_merge] 	read length = 75
INFO 	2016-06-02 18:58:21 	[align_and_merge] 	genome reference FASTA file found at /users/GR/mb/jquilez/assemblies/homo_sapiens/hg38_mmtv/ucsc/hg38_mmtv_chr1-22XYM.fa
INFO 	2016-06-02 18:58:21 	[align_and_merge] 	mapping, processing reads according to restriction enzyme fragments and merging aligments for read1 and read2...
INFO 	2016-06-03 00:08:27 	[align_and_merge] 	output saved in /users/project/4DGenome_no_backup/data/hic/samples/dc3a1e069_ec92aa0bb/logs/hg38_mmtv/dc3a1e069_ec92aa0bb_align_and_merge_paired_end.log
TIME 	2016-06-03 00:10:10 	[align_and_merge] 	step time for completion (seconds) = 18709

INFO 	2016-06-03 00:10:29 	[post_mapping_statistics] 	generating post mapping descriptive statistics plots...
INFO 	2016-06-03 00:33:29 	[post_mapping_statistics] 	fraction of reads mapped read1 = 1.01246422036
INFO 	2016-06-03 00:33:29 	[post_mapping_statistics] 	fraction of reads mapped read2 = 0.822997514909
INFO 	2016-06-03 00:33:29 	[post_mapping_statistics] 	number of pairs in which both read1 and read2 are mapped = 59672672
INFO 	2016-06-03 00:33:29 	[post_mapping_statistics] 	counts-to-distance slope = -1.17522559143
TIME 	2016-06-03 00:33:42 	[post_mapping_statistics] 	step time for completion (seconds) = 1393

INFO 	2016-06-03 00:33:55 	[reads_filtering] 	filtering reads based on multiple quality parameters...
INFO 	2016-06-03 00:33:55 	[reads_filtering] 	filtered reads to be used for subsequent analyses are at /users/project/4DGenome_no_backup/data/hic/samples/dc3a1e069_ec92aa0bb/results/hg38_mmtv/filtered_reads
INFO 	2016-06-03 00:33:55 	[reads_filtering] 	excluded reads due to dangling ends are at /users/project/4DGenome_no_backup/data/hic/samples/dc3a1e069_ec92aa0bb/results/hg38_mmtv/excluded_reads/dangling_ends
INFO 	2016-06-03 00:33:55 	[reads_filtering] 	excluded reads due to self circle are at /users/project/4DGenome_no_backup/data/hic/samples/dc3a1e069_ec92aa0bb/results/hg38_mmtv/excluded_reads/self_circle
INFO 	2016-06-03 00:33:55 	[reads_filtering] 	summary of excluded reads at /users/project/4DGenome_no_backup/data/hic/samples/dc3a1e069_ec92aa0bb/results/hg38_mmtv/excluded_reads/summary_excluded_per_filter
INFO 	2016-06-03 00:46:17 	[reads_filtering] 	numbers and fractions of filtered and excluded reads added to the metadata
TIME 	2016-06-03 00:47:18 	[reads_filtering] 	step time for completion (seconds) = 814

INFO 	2016-06-03 00:47:24 	[post_filtering_statistics] 	generating post filtering descriptive statistics plots... saved at /users/project/4DGenome_no_backup/data/hic/samples/dc3a1e069_ec92aa0bb/plots/hg38_mmtv/post_filtering_statistics:
INFO 	2016-06-03 00:47:24 	[post_filtering_statistics] 	- filtered reads: sequencing coverage along chromosomes, coverage values and interaction matrix
INFO 	2016-06-03 00:47:24 	[post_filtering_statistics] 	- dangling ends: sequencing coverage along chromosomes and coverage values
INFO 	2016-06-03 00:47:24 	[post_filtering_statistics] 	- self-circle ends: sequencing coverage along chromosomes and coverage values
TIME 	2016-06-03 00:59:55 	[post_filtering_statistics] 	step time for completion (seconds) = 751

INFO 	2016-06-03 00:59:58 	[map_to_bam] 	converting MAP to BAM
[bam_sort_core] merging from 42 files...
TIME 	2016-06-03 01:58:22 	[map_to_bam] 	step time for completion (seconds) = 3504

INFO 	2016-06-03 01:58:36 	[downstream_bam] 	perform several downstream analyses
INFO 	2016-06-03 06:52:31 	[downstream_bam] 	number of TADs = 2832
TIME 	2016-06-03 06:52:52 	[downstream_bam] 	step time for completion (seconds) = 17656

INFO 	2016-06-03 06:52:54 	[clean_up] 	deleting the following intermediate files/directories:
INFO 	2016-06-03 06:52:54 	[clean_up] 	/users/project/4DGenome_no_backup/data/hic/samples/dc3a1e069_ec92aa0bb/fastqs_processed
INFO 	2016-06-03 06:52:54 	[clean_up] 	/users/project/4DGenome_no_backup/data/hic/samples/dc3a1e069_ec92aa0bb/mapped_reads
TIME 	2016-06-03 06:52:56 	[clean_up] 	step time for completion (seconds) = 2


INFO 	2016-06-03 06:52:58 	[pipeline] 	completed successfully
TIME 	2016-06-03 06:52:58 	[pipeline] 	total time for completion (seconds) = 46346

